=== APPLICATION CRASH REPORT ===
Time: 2025-06-28 10:54:46.460189
Exception type: <class 'AttributeError'>
Exception value: 'PandasTableModel' object has no attribute 'set_data'

=== TRACEBACK ===
Traceback (most recent call last):
  File "/Users/mohamedabdulkabia/Desktop/school.edu.sl/National/DataCleaningTool/app/views/main_window.py", line 305, in on_load_complete
    self.preview_model.set_data(preview_df)
    ^^^^^^^^^^^^^^^^^^^^^^^^^^^
AttributeError: 'PandasTableModel' object has no attribute 'set_data'. Did you mean: 'setData'?
