2025-06-28 17:12:14,794 - app.main - INFO - Starting application. Log file: /Users/mohamedabdulkabia/Desktop/school.edu.sl/National/DataCleaningTool/logs/app_20250628_171214.log
2025-06-28 17:12:14,794 - app.main - INFO - Global exception handler installed
2025-06-28 17:12:14,795 - app.utils.memory_monitor - INFO - Memory monitoring started
2025-06-28 17:12:14,799 - app.main - INFO - Memory monitoring started
2025-06-28 17:12:14,799 - app.main - CRITICAL - Error during application execution: cannot access local variable 'QApplication' where it is not associated with a value
2025-06-28 17:12:14,799 - app.main - ERROR - Exception details:
Traceback (most recent call last):
  File "/Users/mohamedabdulkabia/Desktop/school.edu.sl/National/DataCleaningTool/app/main.py", line 220, in main
    app = QApplication(sys.argv)
          ^^^^^^^^^^^^
UnboundLocalError: cannot access local variable 'QApplication' where it is not associated with a value
2025-06-28 17:12:15,802 - app.utils.memory_monitor - INFO - Memory monitoring stopped. Peak usage: 256.09375 MB
2025-06-28 17:12:15,802 - app.main - INFO - Memory monitoring stopped
2025-06-28 17:12:15,802 - app.main - INFO - Cleaning up face recognition resources
2025-06-28 17:12:15,804 - app.main - INFO - Running garbage collection
2025-06-28 17:12:15,844 - app.main - INFO - Application shutting down
